Workbook

Sheet Summary Sheet
K2: Sort by Time
B3: Date | C3: Supply ID | D3: Location | E3: In-charge | F3: Engineer | G3: Structure Name | H3: Structure ID | I3: Grade | J3: QTY | K3: Time | L3: Placement By | M3: Planning Remarks
B4: ='Input 1'!D4 -> 46157 | C4: ='Input 1'!D28 -> MVDP/GIC/Per/Pier/001 | D4: ='Input 1'!D5 -> Gorai IC | E4: ='Input 1'!D25 -> Mr. A | F4: ='Input 1'!D26 -> Mr. B | G4: ='Input 1'!D7 -> I Girder | H4: ='Input 1'!D8 -> VGP24 | I4: ='Input 1'!D10 -> M-45 | J4: ='Input 1'!D19 -> 10.6 | K4: ='Input 1'!D23 -> 0.45833333 | L4: ='Input 1'!D24 -> Boom placer | M4: Send Back
B11: Total | J11: =SUM(J4:J10) -> 10.6
B14: ADD | C14: Send Back | D14: Hold | K14: FINAL SEND
B17: Requistion to site planning by 5:30 p.m.
B18: Site planning validates the entries
B19: To be validated and sent to production team by 7:30 p.m.
B21: Send for Production

Sheet Process Flow
C5: Concrete Requisition
B12: Stakeholder | D12: Execution Team | F12: Planning Team | H12: Production Team | J12: Production Team | L12: Final Report
B14: Responsibilities | D14: Data input | F14: Data validation | H14: Dispatch as per Validation | J14: Input actual production | L14: Dashboard
F15: Once validated, a compiled mail of approved IDs sent to production team | H15: Intimation to execution team about dispatch plan | J15: Input TM nos | L15: Production Summary Material usage summary Reconciliation of mix vs actual
J16: Update time for concrete delivery
J17: Update acknowledgement of concrete receipt by site
J18: Link plant production report to the excel for direct input

Sheet Dashboard
A6: =60*2 -> 120 | X6: Location | Y6: Activity | Z6: Theoratical | AA6: Production | AB6: Wastage
A7: =A6 -> 120
A8: =A7*90% -> 108
A9: =10 -> 10
A10: =15 -> 15 | U10: =250000/72 -> 3472.2222
A11: =A8*A9*A10 -> 16200

Sheet Production Team
Y1: Batch Wise Report
C2: Input from Planning team | O2: Input from Production team | Y2: Input from Production team
C3: Production
C4: Date | D4: Supply ID | E4: Location | F4: In-charge | G4: Engineer | H4: Structure Name | I4: Structure ID | J4: Grade | K4: QTY | L4: Time | M4: Placement By | N4: Instruction from Planning | O4: Batching Plant ID | P4: Allocated vehicle | Q4: Grade | R4: Quantity Desptached | S4: Despatch time | T4: Receipt location | U4: Receipt at site | V4: Release from site | W4: Return to Plant
C5: ='Summary Sheet'!B4 -> 46157 | D5: ='Summary Sheet'!C4 -> MVDP/GIC/Per/Pier/001 | E5: ='Summary Sheet'!D4 -> Gorai IC | F5: ='Summary Sheet'!E4 -> Mr. A | G5: ='Summary Sheet'!F4 -> Mr. B | H5: ='Summary Sheet'!G4 -> I Girder | I5: ='Summary Sheet'!H4 -> VGP24 | J5: ='Summary Sheet'!I4 -> M-45 | ... N5: ='Summary Sheet'!M4 -> Send Back | U5: Time | V5: Time | W5: Time

Sheet Input 1
B2: Concrete Requisition Slip | D2: Refference Details
B3: 1 | C3: RFI no. | D3: --------- | E3: Input by site engineer
B4: =B3+1 -> 2 | C4: Date | D4: =TODAY() -> 46157 | E4: Input by site engineer
B5: =B4+1 -> 3 | C5: Location | D5: Gorai IC | E5: Input by site engineer
B6: =B5+1 -> 4 | C6: Structure Type | D6: Permanent | E6: Input by site engineer
B7: =B6+1 -> 5 | C7: Structure Name | D7: I Girder | E7: Input by site engineer | K7: Location | L7: Structure | M7: Structure Part | N7: Structure ID | O7: Casting ID
B8: =B7+1 -> 6 | C8: Structure ID | D8: VGP24 | E8: Input by site engineer | F8: CDP35-CDP36 | K8: Gorai IC | L8: Permanent | M8: Pile | N8: PL 78 | O8: PL 78-1
B9: =B8+1 -> 7 | C9: Pile ID/Lift ID/Girder ID/Segment ID | D9: Lift 1 | E9: Input by site engineer | K9: Gorai IC | L9: Permanent | M9: Pile Cap | N9: PL 78
B10: =B9+1 -> 8 | C10: Concrete Grade | D10: M-45 | E10: Input by site engineer | K10: Gorai IC | L10: Permanent | M10: Pier | N10: PL 78 | O10: Starter/L1/L2/L3
B11: =B10+1 -> 9 | C11: Drawing No. | D11: O23089-Q-BR-CM-GA-1026(R0) | E11: Input by site engineer | K11: Gorai IC | L11: Permanent | M11: Pier Cap | N11: PL 78 | O11: Precast/CIS
B12: =B11+1 -> 10 | C12: Dimension as per Drawing | E12: Input by site engineer | K12: Precast Yard | L12: Permanent | M12: Segment | N12: PL 78-79 | O12: S1
B13: =B12+0.1 -> 10.1 | C13: Length of Structure (in m) | D13: 4 | E13: Input by site engineer | K13: Gorai IC | L13: Permanent | M13: Deck Slab/Voided Slab | N13: Pl 1B-1A | O13: CIS
B14: =B13+0.1 -> 10.2 | C14: Diameter of Pile/Pier (in m) | D14: 1.5 | E14: Input by site engineer | F14: May not be rquird | K14: Gorai IC | L14: Permanent | M14: Diaphragm | N14: VC P8
B15: =B12+1 -> 11 | C15: Theoritical Qty (in cum) | D15: 10 | E15: Input by site engineer | K15: Precast Yard | L15: Permanent | M15: Girder | N15: VC P8-P9 | O15: G2
B16: =B15+1 -> 12 | C16: Dimension as per Actual at site | E16: Input by site engineer | G16: pier cap? | K16: Gorai IC | L16: Permanent | M16: Stiching Concrete | N16: PL 78
B17: =B16+0.1 -> 12.1 | C17: Length of Structure (in m) | D17: 4.3 | E17: Input by site engineer | G17: Direct input till JQE is fixed | K17: Gorai IC | L17: Permanent | M17: Expansion Joint | N17: PL 78
B18: =B17+0.1 -> 12.2 | C18: Diameter of Pile/Pier (in m) | D18: 1.5 | E18: Input by site engineer | K18: MCW | L18: Permanent | M18: Crash Barrier | N18: PL 78-79 | O18: Right Side
B19: =B15+1 -> 12 | C19: Actual Qty (in cum) | D19: 10.6 | E19: Input by site engineer | K19: CSB | L19: Permanent | M19: Lower Pylon
B20: =B19+1 -> 13 | C20: Qty Difference (in cum) | D20: =D15-D19 -> -0.6 | E20: Input by site engineer
B21: =B20+1 -> 14 | C21: Reason for difference | D21: Concrete for Boom placer | E21: Input by site engineer
B22: =B21+1 -> 15 | C22: Order Quantity (in cum) | D22: =D19 -> 10.6 | E22: Input by site engineer
B23: =B22+1 -> 16 | C23: Time of Pour | D23: 0.45833333 | E23: Input by site engineer
B24: =B23+1 -> 17 | C24: Placement By | D24: Boom placer | E24: Input by site engineer
B25: =B24+1 -> 18 | C25: In-charge Name | D25: Mr. A | E25: Input by site engineer | F25: Manual input
B26: =B25+1 -> 19 | C26: Contact Person / Engineer | D26: Mr. B | E26: Input by site engineer
B27: =B26+1 -> 20 | C27: Contact Number | E27: Input by site engineer
B28: =B27+1 -> 21 | C28: Supply ID | D28: MVDP/GIC/Per/Pier/001 | E28: Generate by System | F28: Sample== MVDP/GIC/Per/Pier/001

Sheet Site Engineers

Sheet CSB ID
B4: Structure ID | C4: Pier ID | D4: Side | E4: Lift No
B5: Lower Pylon | C5: PL 63 | D5: Left | E5: 1/2/3/4
B6: Lower Pylon | C6: PL 63 | D6: Right | E6: 1/2/3/4
B7: Lower Pylon | C7: PL 64 | D7: Left | E7: 1/2/3/4
B8: Lower Pylon | C8: PL 64 | D8: Right | E8: 1/2/3/4
B10: Lower Pylon | C10: PR 63 | D10: Left | E10: 1/2/3/4
B11: Lower Pylon | C11: PR 63 | D11: Right | E11: 1/2/3/4
B12: Lower Pylon | C12: PR 64 | D12: Left | E12: 1/2/3/4
B13: Lower Pylon | C13: PR 64 | D13: Right | E13: 1/2/3/4
B15: Structure ID | C15: Pier ID | D15: Side | E15: Lift No
B16: Upper Pylon | C16: PL 63 | D16: Left | E16: 1 to 12
B17: Upper Pylon | C17: PL 63 | D17: Right | E17: 1 to 12
... B26: Structure ID | C26: Pier ID | D26: Side | E26: Lift No
B27: Pier Table | C27: PL 63 | D27: Left
B28: Pier Table | C28: PL 63 | D28: Right
B30: Structure ID | C30: Pier ID | D30: Side | E30: Lift No
B31: Pier Table | C31: PR 64 | D31: Left
B32: Pier Table | C32: PR 64 | D32: Right

Sheet TAB ID
D1: =SUM(D6:D228) -> 2102.4 | I1: =I41+I130 -> 1012.86 | M1: =M38+M121 -> 973.94 | Q1: =SUM(Q5:Q44) -> 371.97
B2: Main Alignment | G2: Charkop Intrchange | K2: Gorai Intrchange | O2: Jetty
B3: Pier ID | C3: Span ID | D3: Length (m) | E3: Structure ID | G3: Pier ID | H3: Span ID | I3: Length (m) | K3: Pier ID | L3: Span ID | M3: Length (m) | O3: Pier ID | P3: Span ID | Q3: Length (m)
B4: A | C4: Platform In Mangrove Area | G4: A | H4: Platform In Mangrove Area | K4: A | L4: Platform In Marine / Creek | O4: A
B5: A1 | G5: C1 | K5: G1 | O5: J1
B6: A2 | C6: =CONCATENATE(B5," - ",B6) -> A1 - A2 | D6: 9.6 | E6: Left/Right | G6: C2 | H6: =CONCATENATE(G5, "-",G6) -> C1-C2 | I6: 9.6 | K6: G2 | L6: =CONCATENATE(K5, "-",K6) -> G1-G2 | M6: 5.2 | O6: J2 | P6: =CONCATENATE(O5, "-",O6) -> J1-J2 | Q6: 9.6
B7: A3 | C7: =CONCATENATE(B6," - ",B7) -> A2 - A3 | D7: 9.6 | E7: Left/Right | G7: C3 | H7: =CONCATENATE(G6, "-",G7) -> C2-C3 | I7: =AVERAGE(7.41) -> 7.41 | K7: G3 | L7: =CONCATENATE(K6, "-",K7) -> G2-G3 | M7: 9.6 | O7: J3 | P7: =CONCATENATE(O6, "-",O7) -> J2-J3 | Q7: 9.6
B8: A4 | C8: =CONCATENATE(B7," - ",B8) -> A3 - A4 | D8: 9.6 | E8: Left/Right | G8: C4 | H8: =CONCATENATE(G7, "-",G8) -> C3-C4 | I8: 9.6 | K8: G4 | L8: =CONCATENATE(K7, "-",K8) -> G3-G4 | M8: 9.6 | O8: J4 | P8: =CONCATENATE(O7, "-",O8) -> J3-J4 | Q8: 9.6
B9: A5 | C9: =CONCATENATE(B8," - ",B9) -> A4 - A5 | D9: 9.6 | E9: Left/Right | G9: C5 | H9: =CONCATENATE(G8, "-",G9) -> C4-C5 | I9: 9.6 | K9: G5 | L9: =CONCATENATE(K8, "-",K9) -> G4-G5 | M9: 9.6 | O9: J5 | P9: =CONCATENATE(O8, "-",O9) -> J4-J5 | Q9: 9.6
B10: A6 | C10: =CONCATENATE(B9," - ",B10) -> A5 - A6 | D10: 9.6 | E10: Left/Right | G10: C6 | H10: =CONCATENATE(G9, "-",G10) -> C5-C6 | I10: 9.6 | K10: G6 | L10: =CONCATENATE(K9, "-",K10) -> G5-G6 | M10: 9.6 | O10: J6 | P10: =CONCATENATE(O9, "-",O10) -> J5-J6 | Q10: 9.6
B11: A7 | C11: =CONCATENATE(B10," - ",B11) -> A6 - A7 | D11: 9.6 | E11: Left/Right | G11: C7 | H11: =CONCATENATE(G10, "-",G11) -> C6-C7 | I11: 9.6 | K11: G7 | L11: =CONCATENATE(K10, "-",K11) -> G6-G7 | M11: 9.6 | O11: J7 | P11: =CONCATENATE(O10, "-",O11) -> J6-J7 | Q11: 9.6
B12: A8 | C12: =CONCATENATE(B11," - ",B12) -> A7 - A8 | D12: 9.6 | E12: Left/Right | G12: C8 | H12: =CONCATENATE(G11, "-",G12) -> C7-C8 | I12: 9.6 | K12: G8 | L12: =CONCATENATE(K11, "-",K12) -> G7-G8 | M12: 9.6 | O12: J8 | P12: =CONCATENATE(O11, "-",O12) -> J7-J8 | Q12: 9.6
B13: A9 | C13: =CONCATENATE(B12," - ",B13) -> A8 - A9 | D13: 9.6 | E13: Left/Right | G13: C9 | H13: =CONCATENATE(G12, "-",G13) -> C8-C9 | I13: =AVERAGE(4.19) -> 4.19 | K13: G9 | L13: =CONCATENATE(K12, "-",K13) -> G8-G9 | M13: 9.6 | O13: J9 | P13: =CONCATENATE(O12, "-",O13) -> J8-J9 | Q13: 9.6
B14: A10 | C14: =CONCATENATE(B13," - ",B14) -> A9 - A10 | D14: 9.6 | E14: Left/Right | G14: C10 | H14: =CONCATENATE(G13, "-",G14) -> C9-C10 | I14: 9.6 | K14: G10 | L14: =CONCATENATE(K13, "-",K14) -> G9-G10 | M14: 9.6 | O14: J10 | P14: =CONCATENATE(O13, "-",O14) -> J9-J10 | Q14: 7.17
B15: A11 | C15: =CONCATENATE(B14," - ",B15) -> A10 - A11 | D15: 9.6 | E15: Left/Right | G15: C11 | H15: =CONCATENATE(G14, "-",G15) -> C10-C11 | I15: 9.6 | K15: G11 | L15: =CONCATENATE(K14, "-",K15) -> G10-G11 | M15: 9.6 | O15: J11 | P15: =CONCATENATE(O14, "-",O15) -> J10-J11 | Q15: 9.6
B16: A12 | C16: =CONCATENATE(B15," - ",B16) -> A11 - A12 | D16: 9.6 | E16: Left/Right | G16: C12 | H16: =CONCATENATE(G15, "-",G16) -> C11-C12 | I16: 9.6 | K16: G12 | L16: =CONCATENATE(K15, "-",K16) -> G11-G12 | M16: 9.6 | O16: J12 | P16: =CONCATENATE(O15, "-",O16) -> J11-J12 | Q16: 9.6
B17: A13 | C17: =CONCATENATE(B16," - ",B17) -> A12 - A13 | D17: 9.6 | E17: Left/Right | G17: C13 | H17: =CONCATENATE(G16, "-",G17) -> C12-C13 | I17: 9.6 | K17: G13 | L17: =CONCATENATE(K16, "-",K17) -> G12-G13 | O17: J13 | P17: =CONCATENATE(O16, "-",O17) -> J12-J13 | Q17: 9.6
B18: A14 | C18: =CONCATENATE(B17," - ",B18) -> A13 - A14 | D18: 9.6 | E18: Left/Right | G18: C14 | H18: =CONCATENATE(G17, "-",G18) -> C13-C14 | I18: 9.6 | K18: G14 | L18: =CONCATENATE(K17, "-",K18) -> G13-G14 | O18: J14 | P18: =CONCATENATE(O17, "-",O18) -> J13-J14 | Q18: 9.6
B19: A15 | C19: =CONCATENATE(B18," - ",B19) -> A14 - A15 | D19: 9.6 | E19: Left/Right | G19: C15 | H19: =CONCATENATE(G18, "-",G19) -> C14-C15 | I19: =AVERAGE(8.31) -> 8.31 | K19: G15 | L19: =CONCATENATE(K18, "-",K19) -> G14-G15 | O19: J15 | P19: =CONCATENATE(O18, "-",O19) -> J14-J15 | Q19: 9.6
B20: A16 | C20: =CONCATENATE(B19," - ",B20) -> A15 - A16 | D20: 9.6 | E20: Left/Right | G20: C16 | H20: =CONCATENATE(G19, "-",G20) -> C15-C16 | I20: 9.6 | K20: G16 | L20: =CONCATENATE(K19, "-",K20) -> G15-G16 | M20: 9.6 | O20: J16 | P20: =CONCATENATE(O19, "-",O20) -> J15-J16 | Q20: 9.6
B21: A17 | C21: =CONCATENATE(B20," - ",B21) -> A16 - A17 | D21: 9.6 | E21: Left/Right | G21: C17 | H21: =CONCATENATE(G20, "-",G21) -> C16-C17 | I21: 9.6 | K21: G17 | L21: =CONCATENATE(K20, "-",K21) -> G16-G17 | M21: 9.6 | O21: J17 | P21: =CONCATENATE(O20, "-",O21) -> J16-J17 | Q21: 9.6
B22: A18 | C22: =CONCATENATE(B21," - ",B22) -> A17 - A18 | D22: 9.6 | E22: Left/Right | G22: C18 | H22: =CONCATENATE(G21, "-",G22) -> C17-C18 | I22: 9.6 | K22: G18 | L22: =CONCATENATE(K21, "-",K22) -> G17-G18 | M22: 9.6 | O22: J18 | P22: =CONCATENATE(O21, "-",O22) -> J17-J18 | Q22: 9.6
B23: A19 | C23: =CONCATENATE(B22," - ",B23) -> A18 - A19 | D23: 9.6 | E23: Left/Right | G23: C19 | H23: =CONCATENATE(G22, "-",G23) -> C18-C19 | I23: 9.6 | K23: G19 | L23: =CONCATENATE(K22, "-",K23) -> G18-G19 | M23: 9.6 | O23: J19 | P23: =CONCATENATE(O22, "-",O23) -> J18-J19 | Q23: 9.6
B24: A20 | C24: =CONCATENATE(B23," - ",B24) -> A19 - A20 | D24: 9.6 | E24: Left/Right | G24: C20 | H24: =CONCATENATE(G23, "-",G24) -> C19-C20 | I24: 9.6 | K24: G20 | L24: =CONCATENATE(K23, "-",K24) -> G19-G20 | M24: 9.6 | O24: J20 | P24: =CONCATENATE(O23, "-",O24) -> J19-J20 | Q24: 9.6
B25: A21 | C25: =CONCATENATE(B24," - ",B25) -> A20 - A21 | D25: 9.6 | E25: Left/Right | G25: C21 | H25: =CONCATENATE(G24, "-",G25) -> C20-C21 | I25: 9.6 | K25: G21 | L25: =CONCATENATE(K24, "-",K25) -> G20-G21 | M25: 9.6 | O25: J21 | P25: =CONCATENATE(O24, "-",O25) -> J20-J21 | Q25: 9.6
B26: A22 | C26: =CONCATENATE(B25," - ",B26) -> A21 - A22 | D26: 9.6 | E26: Left/Right | G26: C22 | H26: =CONCATENATE(G25, "-",G26) -> C21-C22 | I26: 9.6 | K26: G22 | L26: =CONCATENATE(K25, "-",K26) -> G21-G22 | M26: 9.6 | O26: J22 | P26: =CONCATENATE(O25, "-",O26) -> J21-J22 | Q26: 9.6
B27: A23 | C27: =CONCATENATE(B26," - ",B27) -> A22 - A23 | D27: 9.6 | E27: Left/Right | G27: C23 | H27: =CONCATENATE(G26, "-",G27) -> C22-C23 | I27: 9.6 | K27: G23 | L27: =CONCATENATE(K26, "-",K27) -> G22-G23 | M27: 9.6 | O27: J23 | P27: =CONCATENATE(O26, "-",O27) -> J22-J23 | Q27: 9.6
B28: A24 | C28: =CONCATENATE(B27," - ",B28) -> A23 - A24 | D28: 9.6 | E28: Left/Right | G28: C24 | H28: =CONCATENATE(G27, "-",G28) -> C23-C24 | I28: 9.6 | K28: G24 | L28: =CONCATENATE(K27, "-",K28) -> G23-G24 | M28: 9.6 | O28: J24 | P28: =CONCATENATE(O27, "-",O28) -> J23-J24 | Q28: 9.6
B29: A25 | C29: =CONCATENATE(B28," - ",B29) -> A24 - A25 | D29: 9.6 | E29: Left/Right | G29: C25 | H29: =CONCATENATE(G28, "-",G29) -> C24-C25 | I29: 9.6 | K29: G25 | L29: =CONCATENATE(K28, "-",K29) -> G24-G25 | O29: J25 | P29: =CONCATENATE(O28, "-",O29) -> J24-J25 | Q29: 9.6
B30: A26 | C30: =CONCATENATE(B29," - ",B30) -> A25 - A26 | D30: 9.6 | E30: Left/Right | G30: C26 | H30: =CONCATENATE(G29, "-",G30) -> C25-C26 | I30: 9.6 | K30: G26 | L30: =CONCATENATE(K29, "-",K30) -> G25-G26 | O30: J26 | P30: =CONCATENATE(O29, "-",O30) -> J25-J26 | Q30: 9.6
B31: A27 | C31: =CONCATENATE(B30," - ",B31) -> A26 - A27 | D31: 9.6 | E31: Left/Right | G31: C27 | H31: =CONCATENATE(G30, "-",G31) -> C26-C27 | I31: 9.6 | K31: G27 | L31: =CONCATENATE(K30, "-",K31) -> G26-G27 | O31: J27 | P31: =CONCATENATE(O30, "-",O31) -> J26-J27 | Q31: 9.6
B32: A28 | C32: =CONCATENATE(B31," - ",B32) -> A27 - A28 | D32: 9.6 | E32: Left/Right | G32: C28 | H32: =CONCATENATE(G31, "-",G32) -> C27-C28 | I32: 9.6 | K32: G28 | L32: =CONCATENATE(K31, "-",K32) -> G27-G28 | O32: J28 | P32: =CONCATENATE(O31, "-",O32) -> J27-J28 | Q32: 9.6
B33: A29 | C33: =CONCATENATE(B32," - ",B33) -> A28 - A29 | D33: 9.6 | E33: Left/Right | G33: C29 | H33: =CONCATENATE(G32, "-",G33) -> C28-C29 | I33: 9.6 | K33: G29 | L33: =CONCATENATE(K32, "-",K33) -> G28-G29 | M33: 6.01 | O33: J29 | P33: =CONCATENATE(O32, "-",O33) -> J28-J29 | Q33: 9.6
B34: A30 | C34: =CONCATENATE(B33," - ",B34) -> A29 - A30 | D34: 9.6 | E34: Left/Right | G34: C30 | H34: =CONCATENATE(G33, "-",G34) -> C29-C30 | I34: 9.6 | K34: G30 | L34: =CONCATENATE(K33, "-",K34) -> G29-G30 | M34: 9.6 | O34: J30 | P34: =CONCATENATE(O33, "-",O34) -> J29-J30 | Q34: 9.6
B35: A31 | C35: =CONCATENATE(B34," - ",B35) -> A30 - A31 | D35: 9.6 | E35: Left/Right | G35: C31 | H35: =CONCATENATE(G34, "-",G35) -> C30-C31 | I35: 9.6 | K35: G31 | L35: =CONCATENATE(K34, "-",K35) -> G30-G31 | M35: 9.6 | O35: J31 | P35: =CONCATENATE(O34, "-",O35) -> J30-J31 | Q35: 9.6
B36: A32 | C36: =CONCATENATE(B35," - ",B36) -> A31 - A32 | D36: 9.6 | E36: Left/Right | G36: C32 | H36: =CONCATENATE(G35, "-",G36) -> C31-C32 | I36: 9.6 | K36: G32 | L36: =CONCATENATE(K35, "-",K36) -> G31-G32 | M36: 9.6 | O36: J32 | P36: =CONCATENATE(O35, "-",O36) -> J31-J32 | Q36: 9.6
B37: A33 | C37: =CONCATENATE(B36," - ",B37) -> A32 - A33 | D37: 9.6 | E37: Left/Right | G37: C33 | H37: =CONCATENATE(G36, "-",G37) -> C32-C33 | I37: 9.6 | K37: G33 | L37: =CONCATENATE(K36, "-",K37) -> G32-G33 | M37: 9.6 | O37: J33 | P37: =CONCATENATE(O36, "-",O37) -> J32-J33 | Q37: 9.6
B38: A34 | C38: =CONCATENATE(B37," - ",B38) -> A33 - A34 | D38: 9.6 | E38: Left/Right | G38: C34 | H38: =CONCATENATE(G37, "-",G38) -> C33-C34 | I38: 9.6 | K38: Total (Rm) | M38: =SUM(M5:M37) -> 232.01 | O38: J34 | P38: =CONCATENATE(O37, "-",O38) -> J33-J34 | Q38: 9.6
B39: A35 | C39: =CONCATENATE(B38," - ",B39) -> A34 - A35 | D39: 9.6 | E39: Left/Right | G39: C35 | H39: =CONCATENATE(G38, "-",G39) -> C34-C35 | I39: 2.4 | K39: B | L39: Temporary Jetty | O39: J35 | P39: =CONCATENATE(O38, "-",O39) -> J34-J35 | Q39: 9.6
B40: A36 | C40: =CONCATENATE(B39," - ",B40) -> A35 - A36 | D40: 9.6 | E40: Left/Right | G40: C36 | H40: =CONCATENATE(G39, "-",G40) -> C35-C36 | I40: 9.6 | K40: G34 | O40: J36 | P40: =CONCATENATE(O39, "-",O40) -> J35-J36 | Q40: 9.6
...

Sheet Input 2
B2: Concrete Requisition Slip | D2: Details | E2: Refference Details
B3: 1 | C3: WIR / RFI no. | E3: --------- | F3: Input by site engineer
B4: =B3+1 -> 2 | C4: Location | E4: Casting Yard | F4: Input by site engineer
B5: =B4+1 -> 3 | C5: Structure Type | E5: Enabling | F5: Input by site engineer
B6: =B5+1 -> 4 | C6: Structure Name | E6: Gantry Track | F6: Input by site engineer
B7: =B6+1 -> 5 | C7: Concrete Grade | E7: M-30 | F7: Input by site engineer
B8: =B7+1 -> 6 | C8: Drawing No. | F8: Input by site engineer
B9: =B8+1 -> 7 | C9: Dimension as per Drawing | F9: Input by site engineer
B10: =B9+0.1 -> 7.1 | C10: Length of Structure (in m) | E10: 15 | F10: Input by site engineer
B11: =B10+0.1 -> 7.2 | C11: Width of Structure (in m) | E11: 3 | F11: Input by site engineer
B12: =B11+0.1 -> 7.3 | C12: Height of Structure (in m) | E12: 0.3 | F12: Input by site engineer
B13: =B12+0.1 -> 7.4 | C13: Diameter of Pile/Pier (in m) | F13: Input by site engineer | H13: pier cap?
B14: =B13+0.1 -> 7.5 | C14: Cross Section of Structure (in sqm) | E14: =IF(E6="Pile",PI()*E13/2,E11*E12) -> 0.9 | F14: Input by site engineer
B15: =B9+1 -> 8 | C15: Theoritical Qty (in cum) | E15: =E14*E10 -> 13.5 | F15: Input by site engineer
B16: =B15+1 -> 9 | C16: Dimension as per Actual at site | F16: Input by site engineer
B17: =B16+0.1 -> 9.1 | C17: Length of Structure (in m) | E17: 15 | F17: Input by site engineer
B18: =B17+0.1 -> 9.2 | C18: Width of Structure (in m) | E18: 3 | F18: Input by site engineer
B19: =B18+0.1 -> 9.3 | C19: Height of Structure (in m) | E19: 0.3 | F19: Input by site engineer
B20: =B19+0.1 -> 9.4 | C20: Diameter of Pile/Pier (in m) | E20: 1.5 | F20: Input by site engineer
B21: =B20+0.1 -> 9.5 | C21: Cross Section of Structure (in sqm) | E21: =IF(E6="Pile",PI()*E20/2,E18*E19) -> 0.9 | F21: Input by site engineer
B22: =B15+1 -> 9 | C22: Actual Qty (in cum) | E22: =E21*E17 -> 13.5 | F22: Input by site engineer
B23: =B22+1 -> 10 | C23: Qty Difference (in cum) | E23: =E15-E22 -> 0 | F23: Input by site engineer
B24: =B23+1 -> 11 | C24: Reason for difference | F24: Input by site engineer
B25: =B24+1 -> 12 | C25: Order Quantity (in cum) | E25: =E22 -> 13.5 | F25: Input by site engineer
B26: =B25+1 -> 13 | C26: Production Plant | E26: DHV CP 30 | F26: Input by Production team?
B27: =B26+1 -> 14 | C27: Time of Pour | E27: 11am | F27: Input by site engineer
B28: =B27+1 -> 15 | C28: Placement By | E28: Manual | F28: Input by site engineer
B29: =B28+1 -> 16 | C29: Contact Person / Engineer
B30: =B29+1 -> 17 | C30: Contact Number

Sheet Data Validation
B3: Production Plant | D3: Grade of Concrete | F3: Location | H3: Structure | J3: Component | L3: Placement by | N3: Pier lift | O3: Pier Cap | P3: Girder | Q3: Segment
C4: RMC | E4: M-10 | G4: Gorai IC | I4: Permanent | J4: Permanent | M4: Direct - Chute | N4: Starter | O4: Cast In Situ | T4: Dropdown
C5: CY CP 60 | E5: M-20 | G5: Charkop IC | I5: Enabling | K5: Pile | M5: Boom placer | N5: Lift 1 | O5: Precast | P5: Precast | Q5: Precast | T5: Hold
C6: DHV CP 60 | E6: M-25 | G6: Main Carraigeway | K6: Pile cap | N6: Lift 2 | T6: Proceed
E7: M-30 | G7: Casting Yard | K7: Pier | N7: Lift 3 | T7: Send Back
E8: M-45 | K8: Pier Cap | N8: Lift 4
E9: M-45P | K9: Segment
E10: M-50 | K10: I Girder
E11: M-55 | K11: Diaphragm
E12: M-60 | K12: Deck Slab
K13: Segment Stiching
K14: Voided Slab
K15: Pedestal
K16: Seismic Restrainer
K17: Crash Barrier
K18: Expansion Joint
K19: Steel Bridge
K20: Cable Stay Bridge
J22: Enabling | K22: Casting Yard
K23: Site Establishment
K24: Gantry Track
K25: Casting Bed
K26: Stacking Bed
K27: TAB
K28: Labor colony

Sheet Location Tracker
B3: Pricing Center | C3: Location | D3: Side | E3: Chainage | F3: Pier ID | G3: Span ID
B6: Main Alignment | C6: Main Viaduct | D6: LHS | E6: 11000 | F6: PL1B
B7: Main Alignment | C7: Main Viaduct | D7: LHS | E7: 11026.774 | F7: PL1A | G7: =CONCATENATE(F6,"-",F7) -> PL1B-PL1A
B8: Main Alignment | C8: Merging Span | D8: LHS | E8: 11053.549 | F8: PL1 | G8: =CONCATENATE(F7,"-",F8) -> PL1A-PL1
B9: Main Alignment | C9: Merging Span | D9: LHS | E9: 11094.176 | F9: PL2 | G9: =CONCATENATE(F8,"-",F9) -> PL1-PL2
B10: Main Alignment | C10: Merging Span | D10: LHS | E10: 11134.803 | F10: PL3 | G10: =CONCATENATE(F9,"-",F10) -> PL2-PL3
B11: Main Alignment | C11: Merging Span | D11: LHS | E11: 11175.431 | F11: PL4 | G11: =CONCATENATE(F10,"-",F11) -> PL3-PL4
B12: Main Alignment | C12: Main Viaduct | D12: LHS | E12: 11216.058 | F12: PL5 | G12: =CONCATENATE(F11,"-",F12) -> PL4-PL5
B13: Main Alignment | C13: Main Viaduct | D13: LHS | E13: 11256.686 | F13: PL6 | G13: =CONCATENATE(F12,"-",F13) -> PL5-PL6
B14: Main Alignment | C14: Main Viaduct | D14: LHS | E14: 11306.267 | F14: PL7 | G14: =CONCATENATE(F13,"-",F14) -> PL6-PL7
B15: Main Alignment | C15: Main Viaduct | D15: LHS | E15: 11355.85 | F15: PL8 | G15: =CONCATENATE(F14,"-",F15) -> PL7-PL8
B16: Main Alignment | C16: Merging Span | D16: LHS | E16: 11402.447 | F16: PL9 | G16: =CONCATENATE(F15,"-",F16) -> PL8-PL9
B17: Main Alignment | C17: Merging Span | D17: LHS | E17: 11446.059 | F17: PL10 | G17: =CONCATENATE(F16,"-",F17) -> PL9-PL10
B18: Main Alignment | C18: Merging Span | D18: LHS | E18: 11489.671 | F18: PL11 | G18: =CONCATENATE(F17,"-",F18) -> PL10-PL11
... B42: Main Alignment | C42: Main Viaduct | D42: LHS | E42: 12552.653 | F42: PL35 | G42: =CONCATENATE(F41,"-",F42) -> PL34-PL35
B43: Obligatory Span | C43: Basket Bridge | D43: LHS | E43: 12552.653 | F43: PL35
B44: Obligatory Span | C44: Basket Bridge | D44: LHS | E44: 12652.653 | F44: PL36 | G44: =CONCATENATE(F42,"-",F44) -> PL35-PL36
B45: Main Alignment | C45: Main Viaduct | D45: LHS | E45: 12652.653 | F45: PL36
B46: Main Alignment | C46: Main Viaduct | D46: LHS | E46: 12693.919 | F46: PL37 | G46: =CONCATENATE(F44,"-",F46) -> PL36-PL37
B47: Main Alignment | C47: Main Viaduct | D47: LHS | E47: 12734.905 | F47: PL38 | G47: =CONCATENATE(F46,"-",F47) -> PL37-PL38
B48: Main Alignment | C48: Main Viaduct | D48: LHS | E48: 12775.199 | F48: PL39 | G48: =CONCATENATE(F47,"-",F48) -> PL38-PL39
B49: Main Alignment | C49: Main Viaduct | D49: LHS | E49: 12816.182 | F49: PL40 | G49: =CONCATENATE(F48,"-",F49) -> PL39-PL40
B50: Main Alignment | C50: Main Viaduct | D50: LHS | E50: 12857.449 | F50: PL41 | G50: =CONCATENATE(F49,"-",F50) -> PL40-PL41
B51: Main Alignment | C51: Main Viaduct | D51: LHS | E51: 12907.449 | F51: PL42 | G51: =CONCATENATE(F50,"-",F51) -> PL41-PL42
B52: Main Alignment | C52: Main Viaduct | D52: LHS | E52: 12957.449 | F52: PL43 | G52: =CONCATENATE(F51,"-",F52) -> PL42-PL43
B53: Main Alignment | C53: Main Viaduct | D53: LHS | E53: 13007.449 | F53: PL44 | G53: =CONCATENATE(F52,"-",F53) -> PL43-PL44
B54: Main Alignment | C54: Main Viaduct | D54: LHS | E54: 13057.449 | F54: PL45 | G54: =CONCATENATE(F53,"-",F54) -> PL44-PL45
B55: Main Alignment | C55: Main Viaduct | D55: LHS | E55: 13107.449 | F55: PL46 | G55: =CONCATENATE(F54,"-",F55) -> PL45-PL46
B56: Main Alignment | C56: Main Viaduct | D56: LHS | E56: 13157.449 | F56: PL47 | G56: =CONCATENATE(F55,"-",F56) -> PL46-PL47
B57: Main Alignment | C57: Main Viaduct | D57: LHS | E57: 13207.449 | F57: PL48 | G57: =CONCATENATE(F56,"-",F57) -> PL47-PL48
B58: Main Alignment | C58: Main Viaduct | D58: LHS | E58: 13257.449 | F58: PL49 | G58: =CONCATENATE(F57,"-",F58) -> PL48-PL49
... B71: Obligatory Span | C71: Main Viaduct | D71: LHS | E71: 13828.928 | F71: PL62 | G71: =CONCATENATE(F70,"-",F71) -> PL61-PL62
B72: Obligatory Span | C72: Cable Stay Bridge | D72: LHS | E72: 13828.928 | F72: PL62
B73: Obligatory Span | C73: Cable Stay Bridge | D73: LHS | E73: 13903.928 | F73: PL63 | G73: =CONCATENATE(F71,"-",F73) -> PL62-PL63
B74: Obligatory Span | C74: Cable Stay Bridge | D74: LHS | E74: 14053.928 | F74: PL64 | G74: =CONCATENATE(F73,"-",F74) -> PL63-PL64
B75: Obligatory Span | C75: Cable Stay Bridge | D75: LHS | E75: 14128.928 | F75: PL65 | G75: =CONCATENATE(F74,"-",F75) -> PL64-PL65
B76: Obligatory Span | C76: Main Viaduct | D76: LHS | E76: 14128.928 | F76: PL65
B77: Main Alignment | C77: Main Viaduct | D77: LHS | E77: 14163.878 | F77: PL66 | G77: =CONCATENATE(F75,"-",F77) -> PL65-PL66
B78: Main Alignment | C78: Main Viaduct | D78: LHS | E78: 14198.828 | F78: PL67 | G78: =CONCATENATE(F77,"-",F78) -> PL66-PL67
B79: Main Alignment | C79: Main Viaduct | D79: LHS | E79: 14235.35 | F79: PL68 | G79: =CONCATENATE(F78,"-",F79) -> PL67-PL68
...

Sheet Substructure ID
B3: Location | C3: Module | D3: Pier ID | E3: Pile ID | F3: Pile Cap | G3: Pier Cap
B4: Charkop IC | D4: VCP1 | E4: VCP1 | F4: VCP1 | G4: VCP1
B5: Charkop IC | E5: VCP1-P1
B6: Charkop IC | E6: VCP1-P2
B7: Charkop IC | E7: VCP1-P3
B8: Charkop IC | E8: VCP1-P4
B9: Charkop IC | D9: VCP2 | E9: VCP2 | F9: VCP2 | G9: VCP2
B10: Charkop IC | E10: VCP2-P1
B11: Charkop IC | E11: VCP2-P2
B12: Charkop IC | E12: VCP2-P3
B13: Charkop IC | E13: VCP2-P4
B14: Charkop IC | D14: VCP3 | E14: VCP3 | F14: VCP3 | G14: VCP3
B15: Charkop IC | E15: VCP3-P1
B16: Charkop IC | E16: VCP3-P2
B17: Charkop IC | E17: VCP3-P3
B18: Charkop IC | E18: VCP3-P4
B19: Charkop IC | D19: VCP4 | E19: VCP4 | F19: VCP4 | G19: VCP4
B20: Charkop IC | E20: VCP4-P1
B21: Charkop IC | E21: VCP4-P2
B22: Charkop IC | E22: VCP4-P3
B23: Charkop IC | E23: VCP4-P4
B24: Charkop IC | D24: VCP5 | E24: VCP5 | F24: VCP5 | G24: VCP5
B25: Charkop IC | E25: VCP5-P1
B26: Charkop IC | E26: VCP5-P2
B27: Charkop IC | E27: VCP5-P3
B28: Charkop IC | E28: VCP5-P4
B29: Charkop IC | D29: VCP6 | E29: VCP6 | F29: VCP6 | G29: VCP6
B30: Charkop IC | E30: VCP6-P1
B31: Charkop IC | E31: VCP6-P2
B32: Charkop IC | E32: VCP6-P3
B33: Charkop IC | E33: VCP6-P4
B34: Charkop IC | D34: VCP7 | E34: VCP7 | F34: VCP7 | G34: VCP7
B35: Charkop IC | E35: VCP7-P1
B36: Charkop IC | E36: VCP7-P2
B37: Charkop IC | E37: VCP7-P3
B38: Charkop IC | E38: VCP7-P4
B39: Charkop IC | D39: VCP8 | E39: VCP8 | F39: VCP8 | G39: VCP8
B40: Charkop IC | E40: VCP8-P1
B41: Charkop IC | E41: VCP8-P2
B42: Charkop IC | E42: VCP8-P3
...

Sheet Staff List
C2: PROJECT MANAGEMENT | E2: Mail ID
C3: 20368169 | D3: K V Sathyanarayana Murthy | E3: sathyanarayana.murthy@lntecc.com
C4: 164294 | D4: R Surya Rao | E4: rsr@lntecc.com
C5: PLANNING & CONTRACTS DEPARTMENT
C6: 20037715 | D6: Somen Chakraborty | E6: somenc@lntecc.com
C7: 20146611 | D7: Manicavasagam S | E7: smvm@lntecc.com
C8: 20170326 | D8: Ayush Pratap | E8: AYUSHPRATAP@lntecc.com
C9: 20116188 | D9: Deepak Gill | E9: DSGILL@LNTECC.COM
C10: 20099108 | D10: Abhijit Saha | E10: ABHIJITSAHA@lntecc.com
C11: 20188708 | D11: Govind Ram Jat | E11: GOVIND-RAM@lntecc.com
C12: 20193077 | D12: Santosh Mahajan | E12: santoshmahajan@lntecc.com
C13: 20187679 | D13: Jishu Chatterjee | E13: JISHUCHATTERJEE@lntecc.com
C14: STRUCTURE WORK
C15: GORAI INTERCHANGE / MAIN ALIGNMENT SECTION 3 / CABLE STAY BRIDGE
C16: 20175794 | D16: Swapnil Hanchate | E16: sshanchate@lntecc.com
C17: 20157137 | D17: Adarsh Kumar Singh | E17: ADARSH-SINGH@lntecc.com
C18: 20383202 | D18: Shashibhushan Mahato | E18: shashibhushan.mahato@lntecc.com
C19: 20317710 | D19: Raushan Kumar Jha | E19: raushan.jha@lntecc.com
C20: 20143909 | D20: Ajith Kumar M | E20: ajithkm@lntecc.com
C21: 20315341 | D21: Shivam Kumar Gupta | E21: SHIVAMKUMARGUPTA@lntecc.com
C22: MAIN ALIGNMENT SECTION 2 - MARINE WORKS
C23: 20374366 | D23: Pravin Savant | E23: pravin.savant1@lntecc.com
C24: 20031045 | D24: Sonu Jangid | E24: sonujangid@lntecc.com
C25: CHARKOP INTERCHANGE / MAIN ALIGNMENT SECTION 1 / VIEWING TOWER
C26: 173982 | D26: Sunil Kumar Kushwaha | E26: skk@lntecc.com
C27: 20038736 | D27: Vishnu Kumar | E27: VISHNUK@LNTECC.COM
C28: 20193071 | D28: Avijit Sarkar | E28: avii@lntecc.com
C29: 20187365 | D29: Ranjith Kumar P | E29: RANJITH-P@lntecc.com
C30: 20359894 | D30: Vishal Ganesh Bharsakale | E30: vishal.bharsakale@lntecc.com
C31: 10004018 | D31: Shabir Raju Momin | E31: shabir@lntecc.com
C32: 20383242 | D32: Saurabh Pandey | E32: saurabh.pandey6@lntecc.com
C33: 20192859 | D33: Sudip Mondal | E33: MONDAL-SUDIP@lntecc.com
C34: PRECAST YARD
C35: 20368555 | D35: Vinayak Ghorpade | E35: vinayak.ghorpade@lntecc.com
C36: 20188245 | D36: B M Adarsh | E36: BMADARSH@lntecc.com
C37: PRECAST - BAY 1 - MAIN ALIGNMENT SEGMENTS
C38: 20061940 | D38: Rajendra Nath Mahato | E38: rndm@lntecc.com
C39: 20074231 | D39: Soumava Das | E39: SOUMAVADAS@lntecc.com
C40: 20383243 | D40: Aaradhya Tiwari | E40: aaradhya.tiwari@lntecc.com
C41: PRECAST - BAY 2 - EJ / CSB SEGMENTS
...

Sheet MCW Segment ID
H2: 0 | I2: 0
B3: Pier ID | C3: Span ID | D3: Chainage | E3: Module | F3: Span Length | G3: Pier Type | H3: Segment (Nos) | I3: Concrete (cum) | J3: S1 | K3: S2 | L3: S3 | M3: S4 | N3: S5 | O3: S6 | P3: S7 | Q3: S8 | R3: S9 | S3: S10 | T3: S11 | U3: S12 | V3: S13 | W3: S14 | X3: S15 | Y3: S16 | Z3: S17 | AA3: S18 | AB3: S19 | AC3: S20 | AD3: S21 | AE3: S22 | AF3: S23 | AG3: S24 | AH3: S25 | AI3: S26 | AJ3: S27 | AK3: S28 | AL3: S29 | AM3: S30 | AN3: S31 | AO3: S32 | AP3: S33 | AQ3: S34 | AR3: S35 | AS3: S36 | AT3: S37 | AU3: S38 | AV3: S39 | AW3: S40 | AX3: S41 | AY3: S42 | AZ3: S43 | BA3: S42a | BB3: S41a | BC3: S40a | BD3: S39a | BE3: S38a | BF3: S37a | BG3: S36a | BH3: S35a | BI3: S34a | BJ3: S33a | BK3: S32a | BL3: S31a | BM3: S30a | BN3: S29a | BO3: S28a | BP3: S27a | BQ3: S26a | BR3: S25a | BS3: S24a | BT3: S23a | BU3: S22a | BV3: S21a | BW3: S20a | BX3: S19a | BY3: S18a | BZ3: S17a | CA3: S16a | CB3: S15a | CC3: S14a | CD3: S13a | CE3: S12a | CF3: S11a | CG3: S10a | CH3: S9a | CI3: S8b | CJ3: S8a | CK3: S7a | CL3: S6a | CM3: S5a | CN3: S4a | CO3: S3a | CP3: S2a | CQ3: S1a
B4: PL1B | D4: 11000 | G4: EJ | H4: 0 | I4: 0
B5: PL1A | C5: PL1B-PL1A | D5: 11026.774 | E5: 1L | F5: 26.774 | G5: Int. | H5: 0 | I5: 0
B6: PL1 | C6: PL1A-PL1 | D6: 11053.549 | E6: 1L | F6: 26.775 | G6: EJ | H6: 0 | I6: 0
B7: PL2 | C7: PL1-PL2 | D7: 11094.176 | E7: 2L | F7: 40.627 | G7: Int. | H7: 0 | I7: 0 | J7: S1 | K7: S2 | L7: S3 | M7: S4 | N7: S5 | O7: S6 | P7: S7 | Q7: S8 | R7: S9 | S7: S10 | T7: S11 | U7: S12 | V7: S13 | W7: S14
B8: PL3 | C8: PL2-PL3 | D8: 11134.803 | E8: 2L | F8: 40.627 | G8: Int. | H8: 0 | I8: 0 | X8: S15 | Y8: S16 | Z8: S17 | AA8: S18 | AB8: S19 | AC8: S20 | AD8: S21 | BV8: S21a | BW8: S20a | BX8: S19a | BY8: S18a | BZ8: S17a | CA8: S16a | CB8: S15a
B9: PL4 | C9: PL3-PL4 | D9: 11175.431 | E9: 2L | F9: 40.628 | G9: EJ | H9: 0 | I9: 0 | CC9: S14a | CD9: S13a | CE9: S12a | CF9: S11a | CG9: S10a | CH9: S9a | CJ9: S8a | CK9: S7a | CL9: S6a | CM9: S5a | CN9: S4a | CO9: S3a | CP9: S2a | CQ9: S1a
B10: PL5 | C10: PL4-PL5 | D10: 11216.058 | E10: 3L | F10: 40.627 | G10: Int. | H10: 0 | I10: 0 | J10: S1 | K10: S2 | L10: S3 | M10: S4 | N10: S5 | O10: S6 | P10: S7 | Q10: S8 | R10: S9 | S10: S10 | T10: S11 | U10: S12 | V10: S13 | W10: S14
B11: PL6 | C11: PL5-PL6 | D11: 11256.686 | E11: 3L | F11: 40.628 | G11: EJ | H11: 0 | I11: 0 | CC11: S14a | CD11: S13a | CE11: S12a | CF11: S11a | CG11: S10a | CH11: S9a | CJ11: S8a | CK11: S7a | CL11: S6a | CM11: S5a | CN11: S4a | CO11: S3a | CP11: S2a | CQ11: S1a
B12: PL7 | C12: PL6-PL7 | D12: 11306.267 | E12: 3L | F12: 49.581 | G12: Int. | H12: 0 | I12: 0 | J12: S1 | K12: S2 | L12: S3 | M12: S4 | N12: S5 | O12: S6 | P12: S7 | Q12: S8 | R12: S9 | S12: S10 | T12: S11 | U12: S12 | V12: S13 | W12: S14 | X12: S15 | Y12: S16 | Z12: S17
B13: PL8 | C13: PL7-PL8 | D13: 11355.85 | E13: 4L | F13: 49.583 | G13: Int. | H13: 0 | I13: 0 | AA13: S18 | AB13: S19 | AC13: S20 | AD13: S21 | AE13: S22 | AF13: S23 | AG13: S24 | AH13: S25 | AI13: S26 | BR13: S25a | BS13: S24a | BT13: S23a | BU13: S22a | BV13: S21a | BW13: S20a | BX13: S19a | BY13: S18a
B14: PL9 | C14: PL8-PL9 | D14: 11402.447 | E14: 4L | F14: 46.597 | G14: EJ | H14: 0 | I14: 0 | BZ14: S17a | CA14: S16a | CB14: S15a | CC14: S14a | CD14: S13a | CE14: S12a | CF14: S11a | CG14: S10a | CJ14: S8a | CK14: S7a | CL14: S6a | CM14: S5a | CN14: S4a | CO14: S3a | CP14: S2a | CQ14: S1a
B15: PL10 | C15: PL9-PL10 | D15: 11446.059 | E15: 5L | F15: 43.612 | G15: Int. | H15: 0 | I15: 0 | J15: S1 | K15: S2 | L15: S3 | M15: S4 | N15: S5 | O15: S6 | P15: S7 | Q15: S8 | R15: S9 | S15: S10 | T15: S11 | U15: S12 | V15: S13 | W15: S14 | X15: S15
B16: PL11 | C16: PL10-PL11 | D16: 11489.671 | E16: 5L | F16: 43.612 | G16: Int. | H16: 0 | I16: 0 | Y16: S16 | Z16: S17 | AA16: S18 | AB16: S19 | AC16: S20 | AD16: S21 | AE16: S22 | AF16: S23 | AG16: S24 | AH16: S25 | AI16: S26 | AJ16: S27 | AK16: S28 | AL16: S29 | AM16: S30
B17: PL12 | C17: PL11-PL12 | D17: 11533.283 | E17: 5L | F17: 43.612 | G17: Int. | H17: 0 | I17: 0 | AN17: S31 | AO17: S32 | AP17: S33 | AQ17: S34 | AR17: S35 | AS17: S36 | AT17: S37 | AU17: S38 | BF17: S37a | BG17: S36a | BH17: S35a | BI17: S34a | BJ17: S33a | BK17: S32a | BL17: S31a
B18: PL13 | C18: PL12-PL13 | D18: 11576.896 | E18: 5L | F18: 43.613 | G18: Int. | H18: 0 | I18: 0 | BM18: S30a | BN18: S29a | BO18: S28a | BP18: S27a | BQ18: S26a | BR18: S25a | BS18: S24a | BT18: S23a | BU18: S22a | BV18: S21a | BW18: S20a | BX18: S19a | BY18: S18a | BZ18: S17a | CA18: S16a
B19: PL14 | C19: PL13-PL14 | D19: 11617.523 | E19: 5L | F19: 40.627 | G19: EJ | H19: 0 | I19: 0 | CB19: S15a | CC19: S14a | CD19: S13a | CE19: S12a | CF19: S11a | CG19: S10a | CH19: S9a | CK19: S7a | CL19: S6a | CM19: S5a | CN19: S4a | CO19: S3a | CP19: S2a | CQ19: S1a
B20: PL15 | C20: PL14-PL15 | D20: 11658.151 | E20: 6L | F20: 40.628 | G20: Int. | H20: 0 | I20: 0 | J20: S1 | K20: S2 | L20: S3 | M20: S4 | N20: S5 | O20: S6 | P20: S7 | Q20: S8 | R20: S9 | S20: S10 | T20: S11 | U20: S12 | V20: S13 | W20: S14
B21: PL16 | C21: PL15-PL16 | D21: 11698.843 | E21: 6L | F21: 40.692 | G21: Int. | H21: 0 | I21: 0 | X21: S15 | Y21: S16 | Z21: S17 | AA21: S18 | AB21: S19 | AC21: S20 | AD21: S21 | BV21: S21a | BW21: S20a | BX21: S19a | BY21: S18a | BZ21: S17a | CA21: S16a | CB21: S15a
B22: PL17 | C22: PL16-PL17 | D22: 11739.536 | E22: 6L | F22: 40.693 | G22: EJ | H22: 0 | I22: 0 | CC22: S14a | CD22: S13a | CE22: S12a | CF22: S11a | CG22: S10a | CH22: S9a | CJ22: S8a | CK22: S7a | CL22: S6a | CM22: S5a | CN22: S4a | CO22: S3a | CP22: S2a | CQ22: S1a
B23: PL18 | C23: PL17-PL18 | D23: 11780.45 | E23: 7L | F23: 40.914 | G23: Int. | H23: 0 | I23: 0 | J23: S1 | K23: S2 | L23: S3 | M23: S4 | N23: S5 | O23: S6 | P23: S7 | Q23: S8 | R23: S9 | S23: S10 | T23: S11 | U23: S12 | V23: S13 | W23: S14
B24: PL19 | C24: PL18-PL19 | D24: 11821.051 | E24: 7L | F24: 40.601 | G24: Int. | H24: 0 | I24: 0 | X24: S15 | Y24: S16 | Z24: S17 | AA24: S18 | AB24: S19 | AC24: S20 | AD24: S21 | AE24: S22 | AF24: S23 | AG24: S24 | AH24: S25 | AI24: S26 | AJ24: S27 | AK24: S28
B25: PL20 | C25: PL19-PL20 | D25: 11860.944 | E25: 7L | F25: 39.893 | G25: Int. | H25: 0 | I25: 0 | AL25: S29 | AM25: S30 | AN25: S31 | AO25: S32 | AP25: S33 | AQ25: S34 | AR25: S35 | BH25: S35a | BI25: S34a | BJ25: S33a | BK25: S32a | BL25: S31a | BM25: S30a | BN25: S29a
B26: PL21 | C26: PL20-PL21 | D26: 11901.545 | E26: 7L | F26: 40.601 | G26: Int. | H26: 0 | I26: 0 | BO26: S28a | BP26: S27a | BQ26: S26a | BR26: S25a | BS26: S24a | BT26: S23a | BU26: S22a | BV26: S21a | BW26: S20a | BX26: S19a | BY26: S18a | BZ26: S17a | CA26: S16a | CB26: S15a
B27: PL22 | C27: PL21-PL22 | D27: 11942.458 | E27: 7L | F27: 40.913 | G27: EJ | H27: 0 | I27: 0 | CC27: S14a | CD27: S13a | CE27: S12a | CF27: S11a | CG27: S10a | CH27: S9a | CJ27: S8a | CK27: S7a | CL27: S6a | CM27: S5a | CN27: S4a | CO27: S3a | CP27: S2a | CQ27: S1a
B28: PL23 | C28: PL22-PL23 | D28: 11992.041 | E28: 8L | F28: 49.583 | G28: Int. | H28: 0 | I28: 0 | J28: S1 | K28: S2 | L28: S3 | M28: S4 | N28: S5 | O28: S6 | P28: S7 | Q28: S8 | R28: S9 | S28: S10 | T28: S11 | U28: S12 | V28: S13 | W28: S14 | X28: S15 | Y28: S16 | Z28: S17
B29: PL24 | C29: PL23-PL24 | D29: 12041.623 | E29: 8L | F29: 49.582 | G29: Int. | H29: 0 | I29: 0 | AA29: S18 | AB29: S19 | AC29: S20 | AD29: S21 | AE29: S22 | AF29: S23 | AG29: S24 | AH29: S25 | AI29: S26 | AJ29: S27 | AK29: S28 | AL29: S29 | AM29: S30 | AN29: S31 | AO29: S32 | AP29: S33 | AQ29: S34
B30: PL25 | C30: PL24-PL25 | D30: 12091.205 | E30: 8L | F30: 49.582 | G30: Int. | H30: 0 | I30: 0 | AR30: S35 | AS30: S36 | AT30: S37 | AU30: S38 | AV30: S39 | AW30: S40 | AX30: S41 | AY30: S42 | AZ30: S43 | BA30: S42a | BB30: S41a | BC30: S40a | BD30: S39a | BE30: S38a | BF30: S37a | BG30: S36a | BH30: S35a
B31: PL26 | C31: PL25-PL26 | D31: 12140.787 | E31: 8L | F31: 49.582 | G31: Int. | H31: 0 | I31: 0 | BI31: S34a | BJ31: S33a | BK31: S32a | BL31: S31a | BM31: S30a | BN31: S29a | BO31: S28a | BP31: S27a | BQ31: S26a | BR31: S25a | BS31: S24a | BT31: S23a | BU31: S22a | BV31: S21a | BW31: S20a | BX31: S19a | BY31: S18a
B32: PL27 | C32: PL26-PL27 | D32: 12190.369 | E32: 8L | F32: 49.582 | G32: EJ | H32: 0 | I32: 0 | BZ32: S17a | CA32: S16a | CB32: S15a | CC32: S14a | CD32: S13a | CE32: S12a | CF32: S11a | CG32: S10a | CH32: S9a | CJ32: S8a | CK32: S7a | CL32: S6a | CM32: S5a | CN32: S4a | CO32: S3a | CP32: S2a | CQ32: S1a
B33: PL28 | C33: PL27-PL28 | D33: 12239.951 | E33: 9L | F33: 49.582 | G33: Int. | H33: 0 | I33: 0 | J33: S1 | K33: S2 | L33: S3 | M33: S4 | N33: S5 | O33: S6 | P33: S7 | Q33: S8 | R33: S9 | S33: S10 | T33: S11 | U33: S12 | V33: S13 | W33: S14 | X33: S15 | Y33: S16 | Z33: S17
B34: PL29 | C34: PL28-PL29 | D34: 12289.532 | E34: 9L | F34: 49.581 | G34: Int. | H34: 0 | I34: 0 | AA34: S18 | AB34: S19 | AC34: S20 | AD34: S21 | AE34: S22 | AF34: S23 | AG34: S24 | AH34: S25 | AI34: S26 | AJ34: S27 | AK34: S28 | AL34: S29 | AM34: S30 | AN34: S31 | AO34: S32 | AP34: S33 | AQ34: S34
B35: PL30 | C35: PL29-PL30 | D35: 12339.114 | E35: 9L | F35: 49.582 | G35: Int. | H35: 0 | I35: 0 | AR35: S35 | AS35: S36 | AT35: S37 | AU35: S38 | AV35: S39 | AW35: S40 | AX35: S41 | AY35: S42 | AZ35: S43 | BA35: S42a | BB35: S41a | BC35: S40a | BD35: S39a | BE35: S38a | BF35: S37a | BG35: S36a | BH35: S35a
B36: PL31 | C36: PL30-PL31 | D36: 12388.825 | E36: 9L | F36: 49.711 | G36: Int. | H36: 0 | I36: 0 | BI36: S34a | BJ36: S33a | BK36: S32a | BL36: S31a | BM36: S30a | BN36: S29a | BO36: S28a | BP36: S27a | BQ36: S26a | BR36: S25a | BS36: S24a | BT36: S23a | BU36: S22a | BV36: S21a | BW36: S20a | BX36: S19a | BY36: S18a
B37: PL32 | C37: PL31-PL32 | D37: 12438.773 | E37: 9L | F37: 49.948 | G37: EJ | H37: 0 | I37: 0 | BZ37: S17a | CA37: S16a | CB37: S15a | CC37: S14a | CD37: S13a | CE37: S12a | CF37: S11a | CG37: S10a | CH37: S9a | CJ37: S8a | CK37: S7a | CL37: S6a | CM37: S5a | CN37: S4a | CO37: S3a | CP37: S2a | CQ37: S1a
B38: PL33 | C38: PL32-PL33 | D38: 12473.723 | E38: 10L | F38: 34.95 | G38: Int. | H38: 0 | I38: 0 | J38: S1 | K38: S2 | L38: S3 | M38: S4 | N38: S5 | O38: S6 | P38: S7 | Q38: S8 | R38: S9 | S38: S10 | T38: S11 | U38: S12
B39: PL34 | C39: PL33-PL34 | D39: 12508.673 | E39: 10L | F39: 34.95 | G39: EJ | H39: 0 | I39: 0 | CE39: S12a | CF39: S11a | CG39: S10a | CH39: S9a | CJ39: S8a | CK39: S7a | CL39: S6a | CM39: S5a | CN39: S4a | CO39: S3a | CP39: S2a | CQ39: S1a
B40: PL35 | C40: PL34-PL35 | D40: 12552.653 | E40: 11L | F40: 43.98 | G40: EJ | H40: 0 | I40: 0 | J40: S1 | K40: S2 | L40: S3 | M40: S4 | N40: S5 | O40: S6 | P40: S7 | Q40: S8 | CK40: S7a | CL40: S6a | CM40: S5a | CN40: S4a | CO40: S3a | CP40: S2a | CQ40: S1a
B41: PL36 | C41: PL35-PL36 | D41: 12652.653 | E41: 12L | F41: 100 | G41: EJ | H41: 0 | I41: 0
...

Sheet IC Merger Segment
I3: 1 | J3: 0
B4: Location | C4: Span | D4: Side | E4: Module | F4: Ch. From | G4: Ch. To | H4: Length | I4: Segment (Nos) | J4: Total Concrete | K4: LS1 | L4: LS2 | M4: LS3 | N4: LS4 | O4: LS5 | P4: LS6 | Q4: LS7 | R4: LS8 | S4: LS9 | T4: LS10 | U4: LS11 | V4: LS12 | W4: LS13 | X4: LS14 | Y4: LS15 | Z4: LS16 | AA4: LS17 | AB4: LS18 | AC4: LS19 | AD4: LS20 | AE4: LS21 | AF4: LS22 | AG4: LS23 | AH4: LS24 | AI4: LS25 | AJ4: LS26 | AK4: LS27 | AL4: LS28 | AM4: LS29 | AN4: LS30 | AO4: LS31 | AP4: LS32 | AQ4: LS33 | AR4: LS34 | AS4: LS35 | AT4: LS36 | AU4: LS37 | AV4: LS38 | AW4: LS37a | AX4: LS36a | AY4: LS35a | AZ4: LS34a | BA4: LS33a | BB4: LS32a | BC4: LS31a | BD4: LS30a | BE4: LS29a | BF4: LS28a | BG4: LS27a | BH4: LS26a | BI4: LS25a | BJ4: LS24a | BK4: LS23a | BL4: LS22a | BM4: LS21a | BN4: LS20a | BO4: LS19a | BP4: LS18a | BQ4: LS17a | BR4: LS16a | BS4: LS15a | BT4: LS14a | BU4: LS13a | BV4: LS12a | BW4: LS11a | BX4: LS10a | BY4: LS9a | BZ4: LS8a | CA4: LS7a | CB4: LS6a | CC4: LS5a | CD4: LS4a | CE4: LS3a | CF4: LS2a | CG4: LS1a
B5: Charkop IC | C5: PL1-PL2 | D5: LHS | E5: 2L | F5: 11053.549 | G5: 11094.176 | H5: 40.627 | I5: 1 | J5: 0 | K5: LS1 | L5: LS2 | M5: LS3 | N5: LS4 | O5: LS5 | P5: LS6 | Q5: LS7 | R5: LS8 | S5: LS9 | T5: LS10 | U5: LS11 | V5: LS12 | W5: LS13 | X5: LS14 | CH5: 1
B6: Charkop IC | C6: PL2-PL3 | D6: LHS | E6: 2L | F6: 11094.176 | G6: 11134.803 | H6: 40.627 | I6: 0 | J6: 0 | Y6: LS15 | Z6: LS16 | AA6: LS17 | AB6: LS18 | AC6: LS19 | AD6: LS20 | AE6: LS21 | BM6: LS21a | BN6: LS20a | BO6: LS19a | BP6: LS18a | BQ6: LS17a | BR6: LS16a | BS6: LS15a
B7: Charkop IC | C7: PL3-PL4 | D7: LHS | E7: 2L | F7: 11134.803 | G7: 11175.431 | H7: 40.628 | I7: 0 | J7: 0 | BT7: LS14a | BU7: LS13a | BV7: LS12a | BW7: LS11a | BX7: LS10a | BY7: LS9a | BZ7: LS8a | CA7: LS7a | CB7: LS6a | CC7: LS5a | CD7: LS4a | CE7: LS3a | CF7: LS2a | CG7: LS1a
B8: Charkop IC | C8: PL9-PL10 | D8: LHS | E8: 5L | F8: 11402.447 | G8: 11446.059 | H8: 43.612 | I8: 0 | J8: 0 | K8: LS1 | L8: LS2 | M8: LS3 | N8: LS4 | O8: LS5 | P8: LS6 | Q8: LS7 | R8: LS8 | S8: LS9 | T8: LS10 | U8: LS11 | V8: LS12 | W8: LS13 | X8: LS14 | Y8: LS15
B9: Charkop IC | C9: PL10-PL11 | D9: LHS | E9: 5L | F9: 11446.059 | G9: 11489.671 | H9: 43.612 | I9: 0 | J9: 0 | Z9: LS16 | AA9: LS17 | AB9: LS18 | AC9: LS19 | AD9: LS20 | AE9: LS21 | AF9: LS22 | AG9: LS23 | AH9: LS24 | AI9: LS25 | AJ9: LS26 | AK9: LS27 | AL9: LS28 | AM9: LS29 | AN9: LS30
B10: Charkop IC | C10: PL11-PL12 | D10: LHS | E10: 5L | F10: 11489.671 | G10: 11533.283 | H10: 43.612 | I10: 0 | J10: 0 | AO10: LS31 | AP10: LS32 | AQ10: LS33 | AR10: LS34 | AS10: LS35 | AT10: LS36 | AU10: LS37 | AV10: LS38 | AW10: LS37a | AX10: LS36a | AY10: LS35a | AZ10: LS34a | BA10: LS33a | BB10: LS32a | BC10: LS31a
B11: Charkop IC | C11: PL12-PL13 | D11: LHS | E11: 5L | F11: 11533.283 | G11: 11576.896 | H11: 43.613 | I11: 0 | J11: 0 | BD11: LS30a | BE11: LS29a | BF11: LS28a | BG11: LS27a | BH11: LS26a | BI11: LS25a | BJ11: LS24a | BK11: LS23a | BL11: LS22a | BM11: LS21a | BN11: LS20a | BO11: LS19a | BP11: LS18a | BQ11: LS17a | BR11: LS16a
B12: Charkop IC | C12: PL13-PL14 | D12: LHS | E12: 5L | F12: 11576.896 | G12: 11617.523 | H12: 40.627 | I12: 0 | J12: 0 | BS12: LS15a | BT12: LS14a | BU12: LS13a | BV12: LS12a | BW12: LS11a | BX12: LS10a | BY12: LS9a | CA12: LS7a | CB12: LS6a | CC12: LS5a | CD12: LS4a | CE12: LS3a | CF12: LS2a | CG12: LS1a
B13: Gorai IC | C13: PL70-PL71 | D13: LHS | E13: 22L | F13: 14311.27 | G13: 14349.23 | H13: 37.96 | I13: 0 | J13: 0 | K13: LS1 | L13: LS2 | M13: LS3 | N13: LS4 | O13: LS5 | P13: LS6 | Q13: LS7 | R13: LS8 | S13: LS9 | T13: LS10 | U13: LS11 | V13: LS12 | W13: LS13
B14: Gorai IC | C14: PL71-PL72 | D14: LHS | E14: 22L | F14: 14349.23 | G14: 14387.19 | H14: 37.96 | I14: 0 | J14: 0 | X14: LS14 | Y14: LS15 | Z14: LS16 | AA14: LS17 | AB14: LS18 | AC14: LS19 | AD14: LS20 | BO14: LS19a | BP14: LS18a | BQ14: LS17a | BR14: LS16a | BS14: LS15a | BT14: LS14a
B15: Gorai IC | C15: PL72-PL73 | D15: LHS | E15: 22L | F15: 14387.19 | G15: 14425.15 | H15: 37.96 | I15: 0 | J15: 0 | BU15: LS13a | BV15: LS12a | BW15: LS11a | BX15: LS10a | BY15: LS9a | BZ15: LS8a | CA15: LS7a | CB15: LS6a | CC15: LS5a | CD15: LS4a | CE15: LS3a | CF15: LS2a | CG15: LS1a
B16: Gorai IC | C16: PL76-PL77 | D16: LHS | E16: 24L | F16: 14575.15 | G16: 14616.12 | H16: 40.97 | I16: 0 | J16: 0 | K16: LS1 | L16: LS2 | M16: LS3 | N16: LS4 | O16: LS5 | P16: LS6 | Q16: LS7 | R16: LS8 | S16: LS9 | T16: LS10 | U16: LS11 | V16: LS12 | W16: LS13 | X16: LS14
B17: Gorai IC | C17: PL77-PL78 | D17: LHS | E17: 24L | F17: 14616.12 | G17: 14657.09 | H17: 40.97 | I17: 0 | J17: 0 | Y17: LS15 | Z17: LS16 | AA17: LS17 | AB17: LS18 | AC17: LS19 | AD17: LS20 | AE17: LS21 | AF17: LS22 | AG17: LS23 | AH17: LS24 | AI17: LS25 | AJ17: LS26 | AK17: LS27 | AL17: LS28
B18: Gorai IC | C18: PL78-PL79 | D18: LHS | E18: 24L | F18: 14657.09 | G18: 14698.06 | H18: 40.97 | I18: 0 | J18: 0 | AM18: LS29 | AN18: LS30 | AO18: LS31 | AP18: LS32 | AQ18: LS33 | AR18: LS34 | AS18: LS35 | AY18: LS35a | AZ18: LS34a | BA18: LS33a | BB18: LS32a | BC18: LS31a | BD18: LS30a | BE18: LS29a
B19: Gorai IC | C19: PL79-PL80 | D19: LHS | E19: 24L | F19: 14698.06 | G19: 14739.03 | H19: 40.97 | I19: 0 | J19: 0 | BF19: LS28a | BG19: LS27a | BH19: LS26a | BI19: LS25a | BJ19: LS24a | BK19: LS23a | BL19: LS22a | BM19: LS21a | BN19: LS20a | BO19: LS19a | BP19: LS18a | BQ19: LS17a | BR19: LS16a | BS19: LS15a
B20: Gorai IC | C20: PL80-PL81 | D20: LHS | E20: 24L | F20: 14739.03 | G20: 14780 | H20: 40.97 | I20: 0 | J20: 0 | BT20: LS14a | BU20: LS13a | BV20: LS12a | BW20: LS11a | BX20: LS10a | BY20: LS9a | BZ20: LS8a | CA20: LS7a | CB20: LS6a | CC20: LS5a | CD20: LS4a | CE20: LS3a | CF20: LS2a | CG20: LS1a
B22: Location | C22: Span | D22: Side | E22: Module | F22: Ch. From | G22: Ch. To | H22: Length | J22: Total Nos | K22: RS1 | L22: RS2 | M22: RS3 | N22: RS4 | O22: RS5 | P22: RS6 | Q22: RS7 | R22: RS8 | S22: RS9 | T22: RS10 | U22: RS11 | V22: RS12 | W22: RS13 | X22: RS14 | Y22: RS15 | Z22: RS16 | AA22: RS17 | AB22: RS18 | AC22: RS19 | AD22: RS20 | AE22: RS21 | AF22: RS22 | AG22: RS23 | AH22: RS24 | AI22: RS25 | AJ22: RS26 | AK22: RS27 | AL22: RS28 | AM22: RS29 | AN22: RS30 | AO22: RS31 | AP22: RS32 | AQ22: RS33 | AR22: RS34 | AS22: RS35 | AT22: RS36 | AU22: RS37 | AV22: RS38 | AW22: RS37a | AX22: RS36a | AY22: RS35a | AZ22: RS34a | BA22: RS33a | BB22: RS32a | BC22: RS31a | BD22: RS30a | BE22: RS29a | BF22: RS28a | BG22: RS27a | BH22: RS26a | BI22: RS25a | BJ22: RS24a | BK22: RS23a | BL22: RS22a | BM22: RS21a | BN22: RS20a | BO22: RS19a | BP22: RS18a | BQ22: RS17a | BR22: RS16a | BS22: RS15a | BT22: RS14a | BU22: RS13a | BV22: RS12a | BW22: RS11a | BX22: RS10a | BY22: RS9a | BZ22: RS8a | CA22: RS7a | CB22: RS6a | CC22: RS5a | CD22: RS4a | CE22: RS3a | CF22: RS2a | CG22: RS1a
B23: Charkop IC | C23: PR1-PR2 | D23: RHS | E23: 2R | F23: 11053.549 | G23: 11094.176 | H23: 40.627 | I23: 0 | J23: 0 | K23: LS1 | L23: LS2 | M23: LS3 | N23: LS4 | O23: LS5 | P23: LS6 | Q23: LS7 | R23: LS8 | S23: LS9 | T23: LS10 | U23: LS11 | V23: LS12 | W23: LS13 | X23: LS14
B24: Charkop IC | C24: PR2-PR3 | D24: RHS | E24: 2R | F24: 11094.176 | G24: 11134.803 | H24: 40.627 | I24: 0 | J24: 0 | Y24: LS15 | Z24: LS16 | AA24: LS17 | AB24: LS18 | AC24: LS19 | AD24: LS20 | AE24: LS21 | AF24: LS22 | AG24: LS23 | AH24: LS24 | AI24: LS25 | AJ24: LS26 | AK24: LS27 | AL24: LS28
B25: Charkop IC | C25: PR3-PR4 | D25: RHS | E25: 2R | F25: 11134.803 | G25: 11175.431 | H25: 40.628 | I25: 0 | J25: 0 | AM25: LS29 | AN25: LS30 | AO25: LS31 | AP25: LS32 | AQ25: LS33 | AR25: LS34 | AS25: LS35 | AY25: LS35a | AZ25: LS34a | BA25: LS33a | BB25: LS32a | BC25: LS31a | BD25: LS30a | BE25: LS29a
B26: Charkop IC | C26: PR4-PR5 | D26: RHS | E26: 2R | F26: 11175.431 | G26: 11216.058 | H26: 40.627 | I26: 0 | J26: 0 | BF26: LS28a | BG26: LS27a | BH26: LS26a | BI26: LS25a | BJ26: LS24a | BK26: LS23a | BL26: LS22a | BM26: LS21a | BN26: LS20a | BO26: LS19a | BP26: LS18a | BQ26: LS17a | BR26: LS16a | BS26: LS15a
B27: Charkop IC | C27: PR5-PR6 | D27: RHS | E27: 2R | F27: 11216.058 | G27: 11256.686 | H27: 40.628 | I27: 0 | J27: 0 | BT27: LS14a | BU27: LS13a | BV27: LS12a | BW27: LS11a | BX27: LS10a | BY27: LS9a | BZ27: LS8a | CA27: LS7a | CB27: LS6a | CC27: LS5a | CD27: LS4a | CE27: LS3a | CF27: LS2a | CG27: LS1a
B28: Charkop IC | C28: PR12-PR13 | D28: RHS | E28: 5R | F28: 11536.269 | G28: 11576.896 | H28: 40.627 | I28: 0 | J28: 0 | K28: LS1 | L28: LS2 | M28: LS3 | N28: LS4 | O28: LS5 | P28: LS6 | Q28: LS7 | R28: LS8 | S28: LS9 | T28: LS10 | U28: LS11 | V28: LS12 | W28: LS13 | X28: LS14
B29: Charkop IC | C29: PR13-PR14 | D29: RHS | E29: 5R | F29: 11576.896 | G29: 11617.523 | H29: 40.627 | I29: 0 | J29: 0 | Y29: LS15 | Z29: LS16 | AA29: LS17 | AB29: LS18 | AC29: LS19 | AD29: LS20 | AE29: LS21 | BM29: LS21a | BN29: LS20a | BO29: LS19a | BP29: LS18a | BQ29: LS17a | BR29: LS16a | BS29: LS15a
B30: Charkop IC | C30: PR14-PR15 | D30: RHS | E30: 5R | F30: 11617.523 | G30: 11658.151 | H30: 40.628 | I30: 0 | J30: 0 | BT30: LS14a | BU30: LS13a | BV30: LS12a | BW30: LS11a | BX30: LS10a | BY30: LS9a | BZ30: LS8a | CA30: LS7a | CB30: LS6a | CC30: LS5a | CD30: LS4a | CE30: LS3a | CF30: LS2a | CG30: LS1a
B31: Gorai IC | C31: PR68-PR69 | D31: RHS | E31: 22R | F31: 14235.35 | G31: 14273.31 | H31: 37.96 | I31: 0 | J31: 0 | K31: LS1 | L31: LS2 | M31: LS3 | N31: LS4 | O31: LS5 | P31: LS6 | Q31: LS7 | R31: LS8 | S31: LS9 | T31: LS10 | U31: LS11 | V31: LS12 | W31: LS13
B32: Gorai IC | C32: PR69-PR70 | D32: RHS | E32: 22R | F32: 14273.31 | G32: 14311.27 | H32: 37.96 | I32: 0 | J32: 0 | X32: LS14 | Y32: LS15 | Z32: LS16 | AA32: LS17 | AB32: LS18 | AC32: LS19 | AD32: LS20 | AE32: LS21 | AF32: LS22 | AG32: LS23 | AH32: LS24 | AI32: LS25 | AJ32: LS26
B33: Gorai IC | C33: PR70-PR71 | D33: RHS | E33: 22R | F33: 14311.27 | G33: 14349.23 | H33: 37.96 | I33: 0 | J33: 0 | AK33: LS27 | AL33: LS28 | AM33: LS29 | AN33: LS30 | AO33: LS31 | AP33: LS32 | AQ33: LS33 | BB33: LS32a | BC33: LS31a | BD33: LS30a | BE33: LS29a | BF33: LS28a | BG33: LS27a
B34: Gorai IC | C34: PR71-PR72 | D34: RHS | E34: 22R | F34: 14349.23 | G34: 14387.19 | H34: 37.96 | I34: 0 | J34: 0 | BH34: LS26a | BI34: LS25a | BJ34: LS24a | BK34: LS23a | BL34: LS22a | BM34: LS21a | BN34: LS20a | BO34: LS19a | BP34: LS18a | BQ34: LS17a | BR34: LS16a | BS34: LS15a | BT34: LS14a
B35: Gorai IC | C35: PR72-PR73 | D35: RHS | E35: 22R | F35: 14387.19 | G35: 14425.15 | H35: 37.96 | I35: 0 | J35: 0 | BU35: LS13a | BV35: LS12a | BW35: LS11a | BX35: LS10a | BY35: LS9a | BZ35: LS8a | CA35: LS7a | CB35: LS6a | CC35: LS5a | CD35: LS4a | CE35: LS3a | CF35: LS2a | CG35: LS1a
B36: Gorai IC | C36: PR78-PR79 | D36: RHS | E36: 25R | F36: 14657.09 | G36: 14698.06 | H36: 40.97 | I36: 0 | J36: 0 | K36: LS1 | L36: LS2 | M36: LS3 | N36: LS4 | O36: LS5 | P36: LS6 | Q36: LS7 | R36: LS8 | S36: LS9 | T36: LS10 | U36: LS11 | V36: LS12 | W36: LS13 | X36: LS14
B37: Gorai IC | C37: PR79-PR80 | D37: RHS | E37: 25R | F37: 14698.06 | G37: 14739.03 | H37: 40.97 | I37: 0 | J37: 0 | Y37: LS15 | Z37: LS16 | AA37: LS17 | AB37: LS18 | AC37: LS19 | AD37: LS20 | AE37: LS21 | BM37: LS21a | BN37: LS20a | BO37: LS19a | BP37: LS18a | BQ37: LS17a | BR37: LS16a | BS37: LS15a
B38: Gorai IC | C38: PR80-PR81 | D38: RHS | E38: 25R | F38: 14739.03 | G38: 14780 | H38: 40.97 | I38: 0 | J38: 0 | BT38: LS14a | BU38: LS13a | BV38: LS12a | BW38: LS11a | BX38: LS10a | BY38: LS9a | BZ38: LS8a | CA38: LS7a | CB38: LS6a | CC38: LS5a | CD38: LS4a | CE38: LS3a | CF38: LS2a | CG38: LS1a

Sheet IC Girder
D1: No of Girder | F1: 563
B2: Interchange | C2: Sr No | D2: Span ID | E2: Girder ID | F2: Scope | G2: Type of Slab
B3: Charkop IC | C3: 1 | D3: PR12-DCP1 | E3: G1 | F3: 1 | G3: CIS Deck Slab
B4: Charkop IC | C4: 2 | D4: PR12-DCP1 | E4: G2 | F4: 1 | G4: CIS Deck Slab
B5: Charkop IC | C5: 3 | D5: PR12-DCP1 | E5: G3 | F5: 1 | G5: CIS Deck Slab
B6: Charkop IC | C6: 4 | D6: DCP1-DCP2 | E6: G4 | F6: 1 | G6: CIS Deck Slab
B7: Charkop IC | C7: 5 | D7: DCP1-DCP2 | E7: G5 | F7: 1 | G7: CIS Deck Slab
B8: Charkop IC | C8: 6 | D8: DCP1-DCP2 | E8: G6 | F8: 1 | G8: CIS Deck Slab
B9: Charkop IC | C9: 7 | D9: DCP2-DCP3 | E9: G1 | F9: 1 | G9: CIS Deck Slab
B10: Charkop IC | C10: 8 | D10: DCP2-DCP3 | E10: G2 | F10: 1 | G10: CIS Deck Slab
B11: Charkop IC | C11: 9 | D11: DCP2-DCP3 | E11: G3 | F11: 1 | G11: CIS Deck Slab
B12: Charkop IC | C12: 10 | D12: DCP3-DCP4 | E12: G4 | F12: 1 | G12: CIS Deck Slab
B13: Charkop IC | C13: 11 | D13: DCP3-DCP4 | E13: G5 | F13: 1 | G13: CIS Deck Slab
B14: Charkop IC | C14: 12 | D14: DCP3-DCP4 | E14: G6 | F14: 1 | G14: CIS Deck Slab
... B47: Charkop IC | C47: 45 | D47: CVP1-CVP2 | E47: G6 | F47: 1 | G47: CIS Deck Slab
B48: Charkop IC | D48: CVP2-CVP3 | G48: Voided Slab
B49: Charkop IC | D49: CVP3-CVP4 | G49: Voided Slab
B50: Charkop IC | D50: CVP4-CVP5 | G50: Voided Slab
B51: Charkop IC | C51: 46 | D51: CVP5-CVP6 | E51: G1 | F51: 1 | G51: CIS Deck Slab
B52: Charkop IC | C52: 47 | D52: CVP5-CVP6 | E52: G2 | F52: 1 | G52: CIS Deck Slab
B53: Charkop IC | C53: 48 | D53: CVP5-CVP6 | E53: G3 | F53: 1 | G53: CIS Deck Slab
B54: Charkop IC | C54: 49 | D54: CVP6-CVP7 | E54: G1 | F54: 1 | G54: CIS Deck Slab
B55: Charkop IC | C55: 50 | D55: CVP6-CVP7 | E55: G2 | F55: 1 | G55: CIS Deck Slab
B56: Charkop IC | C56: 51 | D56: CVP6-CVP7 | E56: G3 | F56: 1 | G56: CIS Deck Slab
B57: Charkop IC | C57: 52 | D57: CVP7-CVP8 | E57: G1 | F57: 1 | G57: CIS Deck Slab
B58: Charkop IC | C58: 53 | D58: CVP7-CVP8 | E58: G2 | F58: 1 | G58: CIS Deck Slab
B59: Charkop IC | C59: 54 | D59: CVP7-CVP8 | E59: G3 | F59: 1 | G59: CIS Deck Slab
B60: Charkop IC | C60: 55 | D60: CVP8-CVP9 | E60: G1 | F60: 1 | G60: CIS Deck Slab
B61: Charkop IC | C61: 56 | D61: CVP8-CVP9 | E61: G2 | F61: 1 | G61: CIS Deck Slab
B62: Charkop IC | C62: 57 | D62: CVP9-CVP10 | E62: G1 | F62: 1 | G62: CIS Deck Slab
... B164: Charkop IC | C164: 159 | D164: VCP33-VCP34 | E164: G3 | F164: 1 | G164: CIS Deck Slab
B165: Charkop IC | C165: 160 | D165: VCP34-VCP35 | G165: CIS Deck Slab
B166: Charkop IC | C166: 161 | D166: VCP34-VCP35 | G166: CIS Deck Slab
B167: Charkop IC | C167: 162 | D167: VCP34-VCP35 | G167: CIS Deck Slab
B168: Charkop IC | C168: 163 | D168: VCP35-VCP36 | G168: CIS Deck Slab
B169: Charkop IC | C169: 164 | D169: VCP35-VCP36 | G169: CIS Deck Slab
B170: Charkop IC | C170: 165 | D170: VCP35-VCP36 | G170: CIS Deck Slab
B171: Charkop IC | C171: 166 | D171: VCP36-VCP37 | G171: CIS Deck Slab
B172: Charkop IC | C172: 167 | D172: VCP36-VCP37 | G172: CIS Deck Slab
B173: Charkop IC | C173: 168 | D173: VCP36-VCP37 | G173: CIS Deck Slab
...

Sheet MCW Substruture
A2: Location | B2: Module | C2: Pier ID | D2: Pile ID | E2: Pile Cap ID | F2: Pier Cap
A3: MCW | B3: 1L | C3: PL1B | D3: PL1B | E3: PL1B | F3: PL1B
A4: MCW | D4: PL1B-1
A5: MCW | D5: PL1B-2
A6: MCW | D6: PL1B-3
A7: MCW | B7: 1L | C7: PL1A | D7: PL1A | E7: PL1A | F7: PL1A
A8: MCW | D8: PL1A-1
A9: MCW | D9: PL1A-2
A10: MCW | D10: PL1A-3
A11: MCW | B11: 1L | C11: PL1 | D11: PL1 | E11: PL1 | F11: PL1
A12: MCW | D12: PL1-1
A13: MCW | D13: PL1-2
A14: MCW | D14: PL1-3
A15: MCW | D15: PL1-4
A16: MCW | B16: 2L | C16: PL2 | D16: PL2 | E16: PL2 | F16: PL2
A17: MCW | D17: PL2-1
A18: MCW | D18: PL2-2
A19: MCW | D19: PL2-3
A20: MCW | D20: PL2-4
A21: MCW | D21: PL2-5
A22: MCW | D22: PL2-6
A23: MCW | D23: PL2-7
A24: MCW | D24: PL2-8
A25: MCW | B25: 2L | C25: PL3 | D25: PL3 | E25: PL3 | F25: PL3
A26: MCW | D26: PL3-1
A27: MCW | D27: PL3-2
A28: MCW | D28: PL3-3
A29: MCW | D29: PL3-4
A30: MCW | D30: PL3-5
A31: MCW | D31: PL3-6
A32: MCW | D32: PL3-7
A33: MCW | D33: PL3-8
A34: MCW | B34: 2L | C34: PL4 | D34: PL4 | E34: PL4 | F34: PL4
A35: MCW | D35: PL4-1
A36: MCW | D36: PL4-2
A37: MCW | D37: PL4-3
A38: MCW | D38: PL4-4
A39: MCW | D39: PL4-5
A40: MCW | D40: PL4-6
A41: MCW | D41: PL4-7
...
